<?xml version="1.0"?>

<robot xmlns:xacro="http://www.ros.org/wiki/xacro" name="hand_T42_model">

 	<xacro:macro name="base_color">
 		<color rgba="0.1 0.1 0.1 1"/>
 	</xacro:macro>

 	<xacro:macro name="swivel_color">
 		<color rgba="0.1 0.1 0.1 1"/>
 	</xacro:macro>

 	<xacro:macro name="proximal_color">
 		<color rgba="0.16 0.16 0.16 1"/>
 	</xacro:macro>

 	 <xacro:macro name="distal_color">
 		<color rgba="0.16 0.16 0.16 1"/>
 	</xacro:macro>

 	<xacro:macro name="flex_color">
 		<color rgba="0.2 0.2 .2 1"/>
 	</xacro:macro>

  <xacro:macro name="pad_color">
    <color rgba="0.106 0.227 0.631 1"/>
  </xacro:macro>  

  <xacro:property name="rubber_friction_coefficient" value="1.16" />
  <xacro:property name="rubber_contact_stiffness_coefficient" value="1000000.0" />
  <xacro:property name="rubber_contact_damping_coefficient" value="1.0" />
  <xacro:property name="swivel_distance" value="0.0260" /> <!-- Not sure if this is the right distance for T42 -->

  <link name="world" />

    <link name="rail">
      <visual>
          <origin rpy="0 0 0" xyz="0 0 0"/>
          <geometry>
            <cylinder length="0.8" radius="0.02"/>
          </geometry>
          <material
            name="">
            <xacro:base_color/>
          </material>
      </visual>
      <inertial>
          <origin xyz="0 0 0" rpy="0 0 0"/>
          <mass value="0.1"/>
          <inertia
            ixx="0.0" ixy="0.0" ixz="0.0"
            iyy="0.0" iyz="0.0"
            izz="0.0"/>
      </inertial>
    </link>
    <gazebo reference="rail">
      <selfCollide>false</selfCollide>
      <material>Gazebo/White</material>
    </gazebo>

    <link name="base_link">
      <visual>
          <origin rpy="1.57 -1.57 -1.57" xyz="0.065 0 -0.04"/>
          <geometry>
            <mesh filename="package://hand_simulator/meshes/base_link.STL"/>
          </geometry>
          <material
            name="">
            <xacro:base_color/>
          </material>
      </visual>
      <inertial>
          <origin xyz="0 0 0" rpy="0 0 0"/>
          <mass value="0.1"/>
          <inertia
            ixx="0.0" ixy="0.0" ixz="0.0"
            iyy="0.0" iyz="0.0"
            izz="0.0"/>
      </inertial>
      <!-- <collision>
        <origin rpy="1.57 0 -1.57" xyz="0.06 0.017 0"/>
        <geometry>
          <mesh filename="package://hand_simulator/meshes/base_link.STL"/>
        </geometry>
      </collision> -->
    </link>
    <gazebo reference="base_link">
      <selfCollide>true</selfCollide>
      <material>Gazebo/Black</material>
    </gazebo>

    <link name="swivel_1">
        <visual>
            <material name="white">
                <color rgba="1.0 1.0 1.0 1.0" />
            </material>
            <origin rpy="0 1.57 1.57" xyz="-0.016510 ${swivel_distance} 0" />
            <geometry>
                <mesh filename="package://hand_simulator/meshes/swivel_t42.STL" scale="0.001 0.001 0.001" />
            </geometry>
        </visual>
    </link>
    <gazebo reference="swivel_1">
      <material>Gazebo/Red</material>
    </gazebo>

    <link name="finger_1_1">
        <inertial>
            <origin xyz="-0.015875 -0.009000 -0.071550" />
            <mass value="0.1" />
            <inertia ixx="0.01" ixy="0.0" ixz="0.0" iyy="0.01" iyz="0.0" izz="0.01" />
        </inertial>
        <visual>
            <material name="white">
                <color rgba="1.0 1.0 1.0 1.0" />
            </material>
            <origin xyz="-0.015875 -0.009000 -0.071550" />
            <geometry>
                <mesh filename="package://hand_simulator/meshes/proximal_t42.STL" scale="0.025400 0.025400 0.025400" />
            </geometry>
        </visual>
        <collision>
            <origin xyz="-0.015875 -0.009000 -0.071550" />
            <geometry>
                <mesh filename="package://hand_simulator/meshes/proximal_t42.STL" scale="0.025400 0.025400 0.025400" />
            </geometry>
        </collision>
    </link>
    <gazebo reference="finger_1_1">
      <selfCollide>true</selfCollide>
      <material>Gazebo/Red</material>
    </gazebo>
    
    <link name="finger_1_2">
        <inertial>
            <origin xyz="-0.015875 -0.011709 -0.048006" />
            <mass value="0.1" />
            <inertia ixx="0.01" ixy="0.0" ixz="0.0" iyy="0.01" iyz="0.0" izz="0.01" />
        </inertial>
        <visual>
            <material name="green">
                <color rgba="0.1 1.0 0.1 1.0" />
            </material>
            <origin xyz="-0.015875 -0.011709 -0.048006" />
            <geometry>
                <mesh filename="package://hand_simulator/meshes/distal_t42.STL" scale="0.025400 0.025400 0.025400" />
            </geometry>
        </visual>
        <collision>
            <origin xyz="-0.015875 -0.011709 -0.048006" />
            <geometry>
                <mesh filename="package://hand_simulator/meshes/distal_t42.STL" scale="0.025400 0.025400 0.025400" />
            </geometry>
        </collision>
    </link>
    <gazebo reference="finger_1_2">
      <selfCollide>true</selfCollide>
      <mu1>${rubber_friction_coefficient}</mu1>
      <mu2>${rubber_friction_coefficient}</mu2>
      <kp>${rubber_contact_stiffness_coefficient}</kp>
      <kd>${rubber_contact_damping_coefficient}</kd>
      <material>Gazebo/Red</material>
    </gazebo>

    <link name="swivel_2">
        <visual>
            <material name="white">
                <color rgba="1.0 1.0 1.0 1.0" />
            </material>
            <origin rpy="0 1.57 1.57" xyz="-0.016510 -${swivel_distance} 0" />
            <geometry>
                <mesh filename="package://hand_simulator/meshes/swivel_t42.STL" scale="0.001 0.001 0.001" />
            </geometry>
        </visual>
    </link>
    <gazebo reference="swivel_2">
      <material>Gazebo/Red</material>
    </gazebo>
    
    <link name="finger_2_1">
        <inertial>
            <origin xyz="-0.015875 -0.009000 -0.071550" />
            <mass value="0.1" />
            <inertia ixx="0.01" ixy="0.0" ixz="0.0" iyy="0.01" iyz="0.0" izz="0.01" />
        </inertial>
        <visual>
            <material name="white">
                <color rgba="1.0 1.0 1.0 1.0" />
            </material>
            <origin xyz="-0.015875 -0.009000 -0.071550" />
            <geometry>
                <mesh filename="package://hand_simulator/meshes/proximal_t42.STL" scale="0.025400 0.025400 0.025400" />
            </geometry>
        </visual>
        <collision>
            <origin xyz="-0.015875 -0.009000 -0.071550" />
            <geometry>
                <mesh filename="package://hand_simulator/meshes/proximal_t42.STL" scale="0.025400 0.025400 0.025400" />
            </geometry>
        </collision>
    </link>
    <gazebo reference="finger_2_1">
      <selfCollide>true</selfCollide>
      <material>Gazebo/Red</material>
    </gazebo>

    <link name="finger_2_2">
        <inertial>
            <origin xyz="-0.015875 -0.011709 -0.048006" />
            <mass value="0.1" />
            <inertia ixx="0.01" ixy="0.0" ixz="0.0" iyy="0.01" iyz="0.0" izz="0.01" />
        </inertial>
        <visual>
            <material name="orange">
                <color rgba="0.9 0.3 0.1 1.0" />
            </material>
            <origin xyz="-0.015875 -0.011709 -0.048006" />
            <geometry>
                <mesh filename="package://hand_simulator/meshes/distal_t42.STL" scale="0.025400 0.025400 0.025400" />
            </geometry>
        </visual>
        <collision>
            <origin xyz="-0.015875 -0.011709 -0.048006" />
            <geometry>
                <mesh filename="package://hand_simulator/meshes/distal_t42.STL" scale="0.025400 0.025400 0.025400" />
            </geometry>
        </collision>
    </link>
    <gazebo reference="finger_2_2">
      <selfCollide>true</selfCollide>
      <mu1>${rubber_friction_coefficient}</mu1>
      <mu2>${rubber_friction_coefficient}</mu2>
      <kp>${rubber_contact_stiffness_coefficient}</kp>
      <kd>${rubber_contact_damping_coefficient}</kd>
      <material>Gazebo/Red</material>
    </gazebo>

    <!-- Camera -->
    <xacro:property name="camera_size" value="0.1" /> <!-- Size of square 'camera' box -->
    <link name="camera_link">
        <visual>
            <origin xyz="0 0 0" rpy="0 0 0"/>
            <geometry>
                <box size="${camera_size} ${camera_size} ${camera_size}"/>
            </geometry>
            <material name="black"/>
        </visual>
    </link>
    <gazebo reference="camera_link">
        <material>Gazebo/Black</material>
        <sensor type="camera" name="camera">
            <update_rate>30.0</update_rate>
            <camera name="head">
                <horizontal_fov>1.3962634</horizontal_fov>
                <image>
                <width>800</width>
                <height>800</height>
                <format>R8G8B8</format>
                </image>
                <clip>
                <near>0.02</near>
                <far>300</far>
                </clip>
                <noise>
                <type>gaussian</type>
                <!-- Noise is sampled independently per pixel on each frame.
                    That pixel's noise value is added to each of its color
                    channels, which at that point lie in the range [0,1]. -->
                <mean>0.0</mean>
                <stddev>0.007</stddev>
                </noise>
            </camera>
            <plugin name="camera_controller" filename="libgazebo_ros_camera.so">
                <alwaysOn>true</alwaysOn>
                <updateRate>0.0</updateRate>
                <cameraName>hand/camera</cameraName>
                <imageTopicName>image_raw</imageTopicName>
                <cameraInfoTopicName>camera_info</cameraInfoTopicName>
                <frameName>camera_link</frameName>
                <hackBaseline>0.07</hackBaseline>
                <distortionK1>0.0</distortionK1>
                <distortionK2>0.0</distortionK2>
                <distortionK3>0.0</distortionK3>
                <distortionT1>0.0</distortionT1>
                <distortionT2>0.0</distortionT2>
            </plugin>
        </sensor>
    </gazebo>
    



  <!-- Joints -->

    <joint name="world_to_rail" type="fixed">
        <parent link="world"/>
        <child link="rail"/>
      <selfCollide>false</selfCollide>
        <origin
          xyz="0.37 0 0.4"
          rpy="0 0 0" />
    </joint>

    <joint name="rail_to_camera" type="fixed">
        <parent link="rail"/>
        <child link="camera_link"/>
        <axis xyz="0 0 -1" />
        <origin
          xyz="-0.2 0 0.7"
          rpy="0 1.57 3.14" />
    </joint>

    <joint name="rail_to_base" type="prismatic">
        <origin rpy="0 0 0" xyz="-0.06 0.000000 0.2" />
        <parent link="rail" />
        <child link="base_link" />
        <axis xyz="0 0 1"/>
        <limit effort="1000.0" lower="-100." upper="100." velocity="1"/>
    </joint>  

    <joint name="base_link_to_swivel_1" type="fixed">
        <origin rpy="0 0 0" xyz="0 0.000000 0.000000" />
        <parent link="base_link" />
        <child link="swivel_1" />
    </joint>

    <joint name="base_to_finger_1_1" type="revolute">
        <origin rpy="-1.57079632679 1.57079632679 0" xyz="-0.016510 -${swivel_distance} 0.000000" />
        <parent link="base_link" />
        <child link="finger_1_1" />
        <limit effort="10000" lower="0.0" upper="3.0" velocity="2" />
        <axis xyz="1 0 0" />
        <dynamics damping="5" friction="0.0" />
    </joint>
    
    <joint name="finger_1_1_to_finger_1_2" type="revolute">
        <origin rpy="0 0 0" xyz="0.000000 0.000000 -0.062551" />
        <parent link="finger_1_1" />
        <child link="finger_1_2" />
        <limit effort="10000" lower="0.0" upper="1.57" velocity="2" />
        <axis xyz="1 0 0" />
        <dynamics damping="5" friction="0.0" />
    </joint>

    <joint name="base_link_to_swivel_2" type="fixed">
        <origin rpy="0 0 0" xyz="0 0.000000 0.000000" />
        <parent link="base_link" />
        <child link="swivel_2" />
    </joint>

    <joint name="base_to_finger_2_1" type="revolute">
        <origin rpy="1.57079632679 -1.57079632679 0" xyz="-0.016510 ${swivel_distance} 0.0000" />
        <parent link="base_link" />
        <child link="finger_2_1" />
        <limit effort="10000" lower="0.0" upper="3.0" velocity="2" />
        <axis xyz="1 0 0" />
        <dynamics damping="5" friction="0.0" />
    </joint>

    <joint name="finger_2_1_to_finger_2_2" type="revolute">
        <origin rpy="0 0 0" xyz="0.000000 0.000000 -0.062551" />
        <parent link="finger_2_1" />
        <child link="finger_2_2" />
        <limit effort="10000" lower="0.0" upper="1.57" velocity="2" />
        <axis xyz="1 0 0" />
        <dynamics damping="5" friction="0.0" />
    </joint>
    


 <!-- Transmissions -->

  <transmission name="lift" type="SimpleTransmission">
      <type>transmission_interface/SimpleTransmission</type>
      <actuator name="$lift_motor">
          <mechanicalReduction>1</mechanicalReduction>
      </actuator>
      <joint name="rail_to_base">
          <hardwareInterface>hardware_interface/PositionJointInterface</hardwareInterface>
      </joint>
  </transmission>

  <transmission name="finger1_2_trans" type="SimpleTransmission">
      <type>transmission_interface/SimpleTransmission</type>
      <actuator name="$finger12_motor">
          <mechanicalReduction>1</mechanicalReduction>
      </actuator>
      <joint name="base_to_finger_1_1">
          <hardwareInterface>hardware_interface/EffortJointInterface</hardwareInterface>
      </joint>
  </transmission>

  <transmission name="finger1_3_trans" type="SimpleTransmission">
      <type>transmission_interface/SimpleTransmission</type>
      <actuator name="$finger13_motor">
          <mechanicalReduction>1</mechanicalReduction>
      </actuator>
      <joint name="finger_1_1_to_finger_1_2">
          <hardwareInterface>hardware_interface/EffortJointInterface</hardwareInterface>
      </joint>
  </transmission>

  <transmission name="finger2_2_trans" type="SimpleTransmission">
      <type>transmission_interface/SimpleTransmission</type>
      <actuator name="$finger22_motor">
          <mechanicalReduction>1</mechanicalReduction>
      </actuator>
      <joint name="base_to_finger_2_1">
          <hardwareInterface>hardware_interface/EffortJointInterface</hardwareInterface>
      </joint>
  </transmission>

  <transmission name="finger2_3_trans" type="SimpleTransmission">
      <type>transmission_interface/SimpleTransmission</type>
      <actuator name="$finger23_motor">
          <mechanicalReduction>1</mechanicalReduction>
      </actuator>
      <joint name="finger_2_1_to_finger_2_2">
          <hardwareInterface>hardware_interface/EffortJointInterface</hardwareInterface>
      </joint>
  </transmission>
  
    <gazebo>
      <plugin name="gazebo_ros_control" filename="libgazebo_ros_control.so">
          <robotNamespace>/hand</robotNamespace>
      </plugin>
    </gazebo> 

</robot>
